Workbook

Sheet README
A1: India Startups: State-wise and City-wise Counts
A3: SHEET State_Official (authentic, government data)
A4: Startups recognised by DPIIT, state/UT-wise, as on 30 June 2026. Total 2,40,092.
A5: Source: Lok Sabha Unstarred Question No. 1446, answered 28 July 2026, Ministry of Commerce & Industry (DPIIT), Annexure-I.
A6: https://sansad.in/getFile/lsapps/loksabhaquestions/annex/188/AU1446_N4i3CT.pdf
A7: All 36 state/UT values add up exactly to the official total (check cell on that sheet).
A9: SHEET City_District (portal register, NOT the same base as State_Official)
A10: Number of startups registered on the Startup India portal in each district/city, 712 districts, snapshot Aug 2026.
A11: Source: indianstartupmap.com/cities (independent site, reproduces the Startup India portal register). Not published by the Government itself.
A12: IMPORTANT: this register has 4,53,192 companies, but only about 2,31,835 are DPIIT recognised. So city counts here are higher than the official recognised numbers.
A13: DPIIT-recognised count per city is published only for the top 12 cities (column D of City_District). The rest are not available for free from any public source.
A14: Startup India records a district, not a city. Cities are listed under their district. Names are kept exactly as published, so a few duplicates exist
... A24: Registration is not an operating signal. Many registered startups are dormant or closed (MCA lists 6,789 closed among 2,12,283 recognised as of 31 Jan 2026).

Sheet State_Summary
A1: State summary: official DPIIT count vs portal-register city data
A2: Column B is official (30 Jun 2026). Columns C to G come from the portal register (Aug 2026) and are a different base. Do not divide one by the other.
A4: State / UT | B4: DPIIT recognised (official) | C4: Portal-register startups (sum of listed districts) | D4: Districts listed | E4: Biggest city/district | F4: Its registered startups | G4: Biggest city share of state's listed total
A5: Maharashtra | B5: =INDEX(State_Official!$C$5:$C$40,MATCH(A5,State_Official!$B$5:$B$40,0)) -> 41440 | C5: =SUMIFS(City_District!$C$5:$C$716,City_District!$A$5:$A$716,A5) -> 74005 | D5: =COUNTIF(City_District!$A$5:$A$716,A5) -> 43 | E5: =IFERROR(INDEX(City_District!$B$5:$B$716,MATCH(A5,City_District!$A$5:$A$716,0)),"none listed (under 25)") -> Mumbai | F5: =IFERROR(INDEX(City_District!$C$5:$C$716,MATCH(A5,City_District!$A$5:$A$716,0)),0) -> 34079 | G5: =IF(C5=0,0,F5/C5) -> 0.46049591
A6: Karnataka | B6: =INDEX(State_Official!$C$5:$C$40,MATCH(A6,State_Official!$B$5:$B$40,0)) -> 24026 | C6: =SUMIFS(City_District!$C$5:$C$716,City_District!$A$5:$A$716,A6) -> 41192 | D6: =COUNTIF(City_District!$A$5:$A$716,A6) -> 34 | E6: =IFERROR(INDEX(City_District!$B$5:$B$716,MATCH(A6,City_District!$A$5:$A$716,0)),"none listed (under 25)") -> Bengaluru | F6: =IFERROR(INDEX(City_District!$C$5:$C$716,MATCH(A6,City_District!$A$5:$A$716,0)),0) -> 33982 | G6: =IF(C6=0,0,F6/C6) -> 0.82496601
A7: Uttar Pradesh | B7: =INDEX(State_Official!$C$5:$C$40,MATCH(A7,State_Official!$B$5:$B$40,0)) -> 23678 | C7: =SUMIFS(City_District!$C$5:$C$716,City_District!$A$5:$A$716,A7) -> 44893 | D7: =COUNTIF(City_District!$A$5:$A$716,A7) -> 77 | E7: =IFERROR(INDEX(City_District!$B$5:$B$716,MATCH(A7,City_District!$A$5:$A$716,0)),"none listed (under 25)") -> Noida | F7: =IFERROR(INDEX(City_District!$C$5:$C$716,MATCH(A7,City_District!$A$5:$A$716,0)),0) -> 10942 | G7: =IF(C7=0,0,F7/C7) -> 0.2437351
A8: Delhi | B8: =INDEX(State_Official!$C$5:$C$40,MATCH(A8,State_Official!$B$5:$B$40,0)) -> 22336 | C8: =SUMIFS(City_District!$C$5:$C$716,City_District!$A$5:$A$716,A8) -> 44524 | D8: =COUNTIF(City_District!$A$5:$A$716,A8) -> 10 | E8: =IFERROR(INDEX(City_District!$B$5:$B$716,MATCH(A8,City_District!$A$5:$A$716,0)),"none listed (under 25)") -> Delhi | F8: =IFERROR(INDEX(City_District!$C$5:$C$716,MATCH(A8,City_District!$A$5:$A$716,0)),0) -> 42792 | G8: =IF(C8=0,0,F8/C8) -> 0.96109963
A9: Gujarat | B9: =INDEX(State_Official!$C$5:$C$40,MATCH(A9,State_Official!$B$5:$B$40,0)) -> 21019 | C9: =SUMIFS(City_District!$C$5:$C$716,City_District!$A$5:$A$716,A9) -> 34745 | D9: =COUNTIF(City_District!$A$5:$A$716,A9) -> 42 | E9: =IFERROR(INDEX(City_District!$B$5:$B$716,MATCH(A9,City_District!$A$5:$A$716,0)),"none listed (under 25)") -> Ahmedabad | F9: =IFERROR(INDEX(City_District!$C$5:$C$716,MATCH(A9,City_District!$A$5:$A$716,0)),0) -> 15020 | G9: =IF(C9=0,0,F9/C9) -> 0.43229242
A10: Tamil Nadu | B10: =INDEX(State_Official!$C$5:$C$40,MATCH(A10,State_Official!$B$5:$B$40,0)) -> 15774 | C10: =SUMIFS(City_District!$C$5:$C$716,City_District!$A$5:$A$716,A10) -> 29616 | D10: =COUNTIF(City_District!$A$5:$A$716,A10) -> 42 | E10: =IFERROR(INDEX(City_District!$B$5:$B$716,MATCH(A10,City_District!$A$5:$A$716,0)),"none listed (under 25)") -> Chennai | F10: =IFERROR(INDEX(City_District!$C$5:$C$716,MATCH(A10,City_District!$A$5:$A$716,0)),0) -> 15662 | G10: =IF(C10=0,0,F10/C10) -> 0.52883576
A11: Telangana | B11: =INDEX(State_Official!$C$5:$C$40,MATCH(A11,State_Official!$B$5:$B$40,0)) -> 13622 | C11: =SUMIFS(City_District!$C$5:$C$716,City_District!$A$5:$A$716,A11) -> 23156 | D11: =COUNTIF(City_District!$A$5:$A$716,A11) -> 19 | E11: =IFERROR(INDEX(City_District!$B$5:$B$716,MATCH(A11,City_District!$A$5:$A$716,0)),"none listed (under 25)") -> Hyderabad | F11: =IFERROR(INDEX(City_District!$C$5:$C$716,MATCH(A11,City_District!$A$5:$A$716,0)),0) -> 20860 | G11: =IF(C11=0,0,F11/C11) -> 0.90084643
A12: Haryana | B12: =INDEX(State_Official!$C$5:$C$40,MATCH(A12,State_Official!$B$5:$B$40,0)) -> 12482 | C12: =SUMIFS(City_District!$C$5:$C$716,City_District!$A$5:$A$716,A12) -> 20789 | D12: =COUNTIF(City_District!$A$5:$A$716,A12) -> 25 | E12: =IFERROR(INDEX(City_District!$B$5:$B$716,MATCH(A12,City_District!$A$5:$A$716,0)),"none listed (under 25)") -> Gurugram | F12: =IFERROR(INDEX(City_District!$C$5:$C$716,MATCH(A12,City_District!$A$5:$A$716,0)),0) -> 10448 | G12: =IF(C12=0,0,F12/C12) -> 0.50257348
A13: Kerala | B13: =INDEX(State_Official!$C$5:$C$40,MATCH(A13,State_Official!$B$5:$B$40,0)) -> 9092 | C13: =SUMIFS(City_District!$C$5:$C$716,City_District!$A$5:$A$716,A13) -> 15435 | D13: =COUNTIF(City_District!$A$5:$A$716,A13) -> 27 | E13: =IFERROR(INDEX(City_District!$B$5:$B$716,MATCH(A13,City_District!$A$5:$A$716,0)),"none listed (under 25)") -> Kochi | F13: =IFERROR(INDEX(City_District!$C$5:$C$716,MATCH(A13,City_District!$A$5:$A$716,0)),0) -> 4959 | G13: =IF(C13=0,0,F13/C13) -> 0.3212828
A14: Rajasthan | B14: =INDEX(State_Official!$C$5:$C$40,MATCH(A14,State_Official!$B$5:$B$40,0)) -> 8783 | C14: =SUMIFS(City_District!$C$5:$C$716,City_District!$A$5:$A$716,A14) -> 18670 | D14: =COUNTIF(City_District!$A$5:$A$716,A14) -> 35 | E14: =IFERROR(INDEX(City_District!$B$5:$B$716,MATCH(A14,City_District!$A$5:$A$716,0)),"none listed (under 25)") -> Jaipur | F14: =IFERROR(INDEX(City_District!$C$5:$C$716,MATCH(A14,City_District!$A$5:$A$716,0)),0) -> 9551 | G14: =IF(C14=0,0,F14/C14) -> 0.51156936
A15: Madhya Pradesh | B15: =INDEX(State_Official!$C$5:$C$40,MATCH(A15,State_Official!$B$5:$B$40,0)) -> 8194 | C15: =SUMIFS(City_District!$C$5:$C$716,City_District!$A$5:$A$716,A15) -> 15965 | D15: =COUNTIF(City_District!$A$5:$A$716,A15) -> 49 | E15: =IFERROR(INDEX(City_District!$B$5:$B$716,MATCH(A15,City_District!$A$5:$A$716,0)),"none listed (under 25)") -> Indore | F15: =IFERROR(INDEX(City_District!$C$5:$C$716,MATCH(A15,City_District!$A$5:$A$716,0)),0) -> 5111 | G15: =IF(C15=0,0,F15/C15) -> 0.3201378
A16: West Bengal | B16: =INDEX(State_Official!$C$5:$C$40,MATCH(A16,State_Official!$B$5:$B$40,0)) -> 7775 | C16: =SUMIFS(City_District!$C$5:$C$716,City_District!$A$5:$A$716,A16) -> 17197 | D16: =COUNTIF(City_District!$A$5:$A$716,A16) -> 32 | E16: =IFERROR(INDEX(City_District!$B$5:$B$716,MATCH(A16,City_District!$A$5:$A$716,0)),"none listed (under 25)") -> Kolkata | F16: =IFERROR(INDEX(City_District!$C$5:$C$716,MATCH(A16,City_District!$A$5:$A$716,0)),0) -> 11455 | G16: =IF(C16=0,0,F16/C16) -> 0.66610455
... A40: Lakshadweep | B40: =INDEX(State_Official!$C$5:$C$40,MATCH(A40,State_Official!$B$5:$B$40,0)) -> 3 | C40: =SUMIFS(City_District!$C$5:$C$716,City_District!$A$5:$A$716,A40) -> 0 | D40: =COUNTIF(City_District!$A$5:$A$716,A40) -> 0 | E40: =IFERROR(INDEX(City_District!$B$5:$B$716,MATCH(A40,City_District!$A$5:$A$716,0)),"none listed (under 25)") -> none listed (under 25) | F40: =IFERROR(INDEX(City_District!$C$5:$C$716,MATCH(A40,City_District!$A$5:$A$716,0)),0) -> 0 | G40: =IF(C40=0,0,F40/C40) -> 0
A41: Total | B41: =SUM(B5:B40) -> 240092 | C41: =SUM(C5:C40) -> 443519 | D41: =SUM(D5:D40) -> 712
A43: Note: 'Biggest city/district' is the top row for that state in City_District (data is sorted high to low within each state).
A44: Delhi: the portal lists 'Delhi' as one district plus 9 sub-districts (South, East, West...), so Delhi's biggest 'city' is just the whole of Delhi.

Sheet State_Official
A1: DPIIT-recognised startups by State/UT, as on 30 June 2026
A2: Source: Lok Sabha Unstarred Q.1446 (28 Jul 2026), DPIIT, Annexure-I
A4: Rank | B4: State / UT | C4: DPIIT recognised startups | D4: % of India total
A5: =RANK(C5,$C$5:$C$40) -> 1 | B5: Maharashtra | C5: 41440 | D5: =C5/$C$41 -> 0.1726005
A6: =RANK(C6,$C$5:$C$40) -> 2 | B6: Karnataka | C6: 24026 | D6: =C6/$C$41 -> 0.10006997
A7: =RANK(C7,$C$5:$C$40) -> 3 | B7: Uttar Pradesh | C7: 23678 | D7: =C7/$C$41 -> 0.098620529
A8: =RANK(C8,$C$5:$C$40) -> 4 | B8: Delhi | C8: 22336 | D8: =C8/$C$41 -> 0.093031005
A9: =RANK(C9,$C$5:$C$40) -> 5 | B9: Gujarat | C9: 21019 | D9: =C9/$C$41 -> 0.087545608
A10: =RANK(C10,$C$5:$C$40) -> 6 | B10: Tamil Nadu | C10: 15774 | D10: =C10/$C$41 -> 0.065699815
A11: =RANK(C11,$C$5:$C$40) -> 7 | B11: Telangana | C11: 13622 | D11: =C11/$C$41 -> 0.056736584
A12: =RANK(C12,$C$5:$C$40) -> 8 | B12: Haryana | C12: 12482 | D12: =C12/$C$41 -> 0.051988404
A13: =RANK(C13,$C$5:$C$40) -> 9 | B13: Kerala | C13: 9092 | D13: =C13/$C$41 -> 0.037868817
A14: =RANK(C14,$C$5:$C$40) -> 10 | B14: Rajasthan | C14: 8783 | D14: =C14/$C$41 -> 0.03658181
A15: =RANK(C15,$C$5:$C$40) -> 11 | B15: Madhya Pradesh | C15: 8194 | D15: =C15/$C$41 -> 0.034128584
A16: =RANK(C16,$C$5:$C$40) -> 12 | B16: West Bengal | C16: 7775 | D16: =C16/$C$41 -> 0.03238342
... A40: =RANK(C40,$C$5:$C$40) -> 36 | B40: Lakshadweep | C40: 3 | D40: =C40/$C$41 -> 1.249521e-05
B41: Total (sum of states) | C41: =SUM(C5:C40) -> 240092 | D41: =SUM(D5:D40) -> 1
B42: Official national total (as stated in reply) | C42: 240092
B43: Check: difference (should be 0) | C43: =C41-C42 -> 0

Sheet City_District
A1: Startups registered on the Startup India portal, by district/city (snapshot Aug 2026)
A2: Source: indianstartupmap.com/cities, built from the Startup India register. Registered != DPIIT recognised. Districts with 25+ startups only.
A4: State / UT | B4: City / District (as published) | C4: Registered startups on portal | D4: DPIIT recognised (top 12 cities only) | E4: Rank in India | F4: Rank in state | G4: % of state's listed total
A5: Maharashtra | B5: Mumbai | C5: 34079 | D5: 18750 | E5: =RANK(C5,$C$5:$C$716) -> 2 | F5: =COUNTIFS($A$5:$A$716,A5,$C$5:$C$716,">"&C5)+1 -> 1 | G5: =C5/SUMIFS($C$5:$C$716,$A$5:$A$716,A5) -> 0.46049591
A6: Maharashtra | B6: Pune | C6: 19787 | D6: 11152 | E6: =RANK(C6,$C$5:$C$716) -> 5 | F6: =COUNTIFS($A$5:$A$716,A6,$C$5:$C$716,">"&C6)+1 -> 2 | G6: =C6/SUMIFS($C$5:$C$716,$A$5:$A$716,A6) -> 0.26737383
A7: Maharashtra | B7: Nagpur | C7: 3991 | E7: =RANK(C7,$C$5:$C$716) -> 19 | F7: =COUNTIFS($A$5:$A$716,A7,$C$5:$C$716,">"&C7)+1 -> 3 | G7: =C7/SUMIFS($C$5:$C$716,$A$5:$A$716,A7) -> 0.053928789
A8: Maharashtra | B8: Nashik | C8: 2846 | E8: =RANK(C8,$C$5:$C$716) -> 25 | F8: =COUNTIFS($A$5:$A$716,A8,$C$5:$C$716,">"&C8)+1 -> 4 | G8: =C8/SUMIFS($C$5:$C$716,$A$5:$A$716,A8) -> 0.038456861
A9: Maharashtra | B9: Aurangabad | C9: 1977 | E9: =RANK(C9,$C$5:$C$716) -> 31 | F9: =COUNTIFS($A$5:$A$716,A9,$C$5:$C$716,">"&C9)+1 -> 5 | G9: =C9/SUMIFS($C$5:$C$716,$A$5:$A$716,A9) -> 0.026714411
A10: Maharashtra | B10: Raigad | C10: 1561 | E10: =RANK(C10,$C$5:$C$716) -> 36 | F10: =COUNTIFS($A$5:$A$716,A10,$C$5:$C$716,">"&C10)+1 -> 6 | G10: =C10/SUMIFS($C$5:$C$716,$A$5:$A$716,A10) -> 0.021093169
A11: Maharashtra | B11: Kolhapur | C11: 1023 | E11: =RANK(C11,$C$5:$C$716) -> 50 | F11: =COUNTIFS($A$5:$A$716,A11,$C$5:$C$716,">"&C11)+1 -> 7 | G11: =C11/SUMIFS($C$5:$C$716,$A$5:$A$716,A11) -> 0.01382339
A12: Maharashtra | B12: Ahmednagar | C12: 991 | E12: =RANK(C12,$C$5:$C$716) -> 52 | F12: =COUNTIFS($A$5:$A$716,A12,$C$5:$C$716,">"&C12)+1 -> 8 | G12: =C12/SUMIFS($C$5:$C$716,$A$5:$A$716,A12) -> 0.013390987
A13: Maharashtra | B13: Solapur | C13: 664 | E13: =RANK(C13,$C$5:$C$716) -> 79 | F13: =COUNTIFS($A$5:$A$716,A13,$C$5:$C$716,">"&C13)+1 -> 9 | G13: =C13/SUMIFS($C$5:$C$716,$A$5:$A$716,A13) -> 0.0089723667
A14: Maharashtra | B14: Sangli | C14: 655 | E14: =RANK(C14,$C$5:$C$716) -> 81 | F14: =COUNTIFS($A$5:$A$716,A14,$C$5:$C$716,">"&C14)+1 -> 10 | G14: =C14/SUMIFS($C$5:$C$716,$A$5:$A$716,A14) -> 0.0088507533
A15: Maharashtra | B15: Jalgaon | C15: 609 | E15: =RANK(C15,$C$5:$C$716) -> 86 | F15: =COUNTIFS($A$5:$A$716,A15,$C$5:$C$716,">"&C15)+1 -> 11 | G15: =C15/SUMIFS($C$5:$C$716,$A$5:$A$716,A15) -> 0.0082291737
A16: Maharashtra | B16: Amravati | C16: 579 | E16: =RANK(C16,$C$5:$C$716) -> 91 | F16: =COUNTIFS($A$5:$A$716,A16,$C$5:$C$716,">"&C16)+1 -> 12 | G16: =C16/SUMIFS($C$5:$C$716,$A$5:$A$716,A16) -> 0.0078237957
A17: Maharashtra | B17: Satara | C17: 516 | E17: =RANK(C17,$C$5:$C$716) -> 103 | F17: =COUNTIFS($A$5:$A$716,A17,$C$5:$C$716,">"&C17)+1 -> 13 | G17: =C17/SUMIFS($C$5:$C$716,$A$5:$A$716,A17) -> 0.0069725019
A18: Maharashtra | B18: Nanded | C18: 365 | E18: =RANK(C18,$C$5:$C$716) -> 133 | F18: =COUNTIFS($A$5:$A$716,A18,$C$5:$C$716,">"&C18)+1 -> 14 | G18: =C18/SUMIFS($C$5:$C$716,$A$5:$A$716,A18) -> 0.0049320992
... A47: Maharashtra | B47: Sangamner | C47: 29 | E47: =RANK(C47,$C$5:$C$716) -> 690 | F47: =COUNTIFS($A$5:$A$716,A47,$C$5:$C$716,">"&C47)+1 -> 43 | G47: =C47/SUMIFS($C$5:$C$716,$A$5:$A$716,A47) -> 0.00039186541
A48: Uttar Pradesh | B48: Noida | C48: 10942 | D48: 6335 | E48: =RANK(C48,$C$5:$C$716) -> 9 | F48: =COUNTIFS($A$5:$A$716,A48,$C$5:$C$716,">"&C48)+1 -> 1 | G48: =C48/SUMIFS($C$5:$C$716,$A$5:$A$716,A48) -> 0.2437351
A49: Uttar Pradesh | B49: Lucknow | C49: 7614 | D49: 3621 | E49: =RANK(C49,$C$5:$C$716) -> 12 | F49: =COUNTIFS($A$5:$A$716,A49,$C$5:$C$716,">"&C49)+1 -> 2 | G49: =C49/SUMIFS($C$5:$C$716,$A$5:$A$716,A49) -> 0.16960328
A50: Uttar Pradesh | B50: Ghaziabad | C50: 5710 | E50: =RANK(C50,$C$5:$C$716) -> 13 | F50: =COUNTIFS($A$5:$A$716,A50,$C$5:$C$716,">"&C50)+1 -> 3 | G50: =C50/SUMIFS($C$5:$C$716,$A$5:$A$716,A50) -> 0.12719132
A51: Uttar Pradesh | B51: Kanpur | C51: 2694 | E51: =RANK(C51,$C$5:$C$716) -> 26 | F51: =COUNTIFS($A$5:$A$716,A51,$C$5:$C$716,">"&C51)+1 -> 4 | G51: =C51/SUMIFS($C$5:$C$716,$A$5:$A$716,A51) -> 0.060009356
A52: Uttar Pradesh | B52: Varanasi | C52: 1716 | E52: =RANK(C52,$C$5:$C$716) -> 35 | F52: =COUNTIFS($A$5:$A$716,A52,$C$5:$C$716,">"&C52)+1 -> 5 | G52: =C52/SUMIFS($C$5:$C$716,$A$5:$A$716,A52) -> 0.038224222
A53: Uttar Pradesh | B53: Agra | C53: 1513 | E53: =RANK(C53,$C$5:$C$716) -> 39 | F53: =COUNTIFS($A$5:$A$716,A53,$C$5:$C$716,">"&C53)+1 -> 6 | G53: =C53/SUMIFS($C$5:$C$716,$A$5:$A$716,A53) -> 0.033702359
A54: Uttar Pradesh | B54: Prayagraj | C54: 1463 | E54: =RANK(C54,$C$5:$C$716) -> 40 | F54: =COUNTIFS($A$5:$A$716,A54,$C$5:$C$716,">"&C54)+1 -> 7 | G54: =C54/SUMIFS($C$5:$C$716,$A$5:$A$716,A54) -> 0.0325886
A55: Uttar Pradesh | B55: Meerut | C55: 1423 | E55: =RANK(C55,$C$5:$C$716) -> 41 | F55: =COUNTIFS($A$5:$A$716,A55,$C$5:$C$716,">"&C55)+1 -> 8 | G55: =C55/SUMIFS($C$5:$C$716,$A$5:$A$716,A55) -> 0.031697592
A56: Uttar Pradesh | B56: Gorakhpur | C56: 979 | E56: =RANK(C56,$C$5:$C$716) -> 53 | F56: =COUNTIFS($A$5:$A$716,A56,$C$5:$C$716,">"&C56)+1 -> 9 | G56: =C56/SUMIFS($C$5:$C$716,$A$5:$A$716,A56) -> 0.021807409
A57: Uttar Pradesh | B57: Bareilly | C57: 782 | E57: =RANK(C57,$C$5:$C$716) -> 66 | F57: =COUNTIFS($A$5:$A$716,A57,$C$5:$C$716,">"&C57)+1 -> 10 | G57: =C57/SUMIFS($C$5:$C$716,$A$5:$A$716,A57) -> 0.017419197
A58: Uttar Pradesh | B58: Mathura | C58: 600 | E58: =RANK(C58,$C$5:$C$716) -> 88 | F58: =COUNTIFS($A$5:$A$716,A58,$C$5:$C$716,">"&C58)+1 -> 11 | G58: =C58/SUMIFS($C$5:$C$716,$A$5:$A$716,A58) -> 0.013365113
A59: Uttar Pradesh | B59: Jhansi | C59: 562 | E59: =RANK(C59,$C$5:$C$716) -> 95 | F59: =COUNTIFS($A$5:$A$716,A59,$C$5:$C$716,">"&C59)+1 -> 12 | G59: =C59/SUMIFS($C$5:$C$716,$A$5:$A$716,A59) -> 0.012518655
A60: Uttar Pradesh | B60: Moradabad | C60: 555 | E60: =RANK(C60,$C$5:$C$716) -> 96 | F60: =COUNTIFS($A$5:$A$716,A60,$C$5:$C$716,">"&C60)+1 -> 13 | G60: =C60/SUMIFS($C$5:$C$716,$A$5:$A$716,A60) -> 0.012362729
A61: Uttar Pradesh | B61: Aligarh | C61: 549 | E61: =RANK(C61,$C$5:$C$716) -> 98 | F61: =COUNTIFS($A$5:$A$716,A61,$C$5:$C$716,">"&C61)+1 -> 14 | G61: =C61/SUMIFS($C$5:$C$716,$A$5:$A$716,A61) -> 0.012229078
... A124: Uttar Pradesh | B124: Kasganj | C124: 33 | E124: =RANK(C124,$C$5:$C$716) -> 661 | F124: =COUNTIFS($A$5:$A$716,A124,$C$5:$C$716,">"&C124)+1 -> 77 | G124: =C124/SUMIFS($C$5:$C$716,$A$5:$A$716,A124) -> 0.00073508119
A125: Delhi | B125: Delhi | C125: 42792 | D125: 21250 | E125: =RANK(C125,$C$5:$C$716) -> 1 | F125: =COUNTIFS($A$5:$A$716,A125,$C$5:$C$716,">"&C125)+1 -> 1 | G125: =C125/SUMIFS($C$5:$C$716,$A$5:$A$716,A125) -> 0.96109963
A126: Delhi | B126: South | C126: 360 | E126: =RANK(C126,$C$5:$C$716) -> 135 | F126: =COUNTIFS($A$5:$A$716,A126,$C$5:$C$716,">"&C126)+1 -> 2 | G126: =C126/SUMIFS($C$5:$C$716,$A$5:$A$716,A126) -> 0.0080855269
A127: Delhi | B127: East | C127: 310 | E127: =RANK(C127,$C$5:$C$716) -> 148 | F127: =COUNTIFS($A$5:$A$716,A127,$C$5:$C$716,">"&C127)+1 -> 3 | G127: =C127/SUMIFS($C$5:$C$716,$A$5:$A$716,A127) -> 0.0069625371
A128: Delhi | B128: West | C128: 238 | E128: =RANK(C128,$C$5:$C$716) -> 187 | F128: =COUNTIFS($A$5:$A$716,A128,$C$5:$C$716,">"&C128)+1 -> 4 | G128: =C128/SUMIFS($C$5:$C$716,$A$5:$A$716,A128) -> 0.0053454317
A129: Delhi | B129: South East | C129: 221 | E129: =RANK(C129,$C$5:$C$716) -> 204 | F129: =COUNTIFS($A$5:$A$716,A129,$C$5:$C$716,">"&C129)+1 -> 5 | G129: =C129/SUMIFS($C$5:$C$716,$A$5:$A$716,A129) -> 0.0049636151
A130: Delhi | B130: South West | C130: 173 | E130: =RANK(C130,$C$5:$C$716) -> 257 | F130: =COUNTIFS($A$5:$A$716,A130,$C$5:$C$716,">"&C130)+1 -> 6 | G130: =C130/SUMIFS($C$5:$C$716,$A$5:$A$716,A130) -> 0.0038855449
A131: Delhi | B131: North West | C131: 160 | E131: =RANK(C131,$C$5:$C$716) -> 273 | F131: =COUNTIFS($A$5:$A$716,A131,$C$5:$C$716,">"&C131)+1 -> 7 | G131: =C131/SUMIFS($C$5:$C$716,$A$5:$A$716,A131) -> 0.0035935675
...
